Workbook
Name SAL_PAGO_ESTADO: SALON!$T$14:$V$14
Name FIT_INS_CUOTA: FITNESS!$B$12:$D$12
Name FIT_INS_MODALIDAD: FITNESS!$P$10:$R$10
Name SAL_PAGO_DNI: SALON!$T$10:$V$10
Name FIT_INS_TURNO: FITNESS!$P$12:$R$12
Name AUL_INS_MODALIDAD: AULA!$P$10:$R$10
Name AUL_INS_HORARIO: AULA!$P$12:$R$12
Name FIT_PAGO_APELLIDO: FITNESS!$T$12:$V$12
Name SAL_INS_TEL: SALON!$J$10:$L$10
Name SAL_INS_INSTRUCTOR: SALON!$K$12:$O$12
Name SAL_INS_NOMBRE: SALON!$B$10:$D$10
Name AUL_INS_APELLIDO: AULA!$E$10:$G$10
Name AUL_PAGO_INSTRUCTOR: AULA!$W$12:$Z$12
Name AUL_PAGO_MONTO: AULA!$AA$12:$AD$12
Name SAL_PAGO_INSTRUCTOR: SALON!$W$12:$Z$12
Name AUL_PAGO_ACTIVIDAD: AULA!$T$12:$V$12
Name FIT_INS_TEL: FITNESS!$J$10:$L$10
Name FIT_INS_OBS: FITNESS!$B$14:$R$14
Name AUL_INS_INSTRUCTOR: AULA!$K$12:$O$12
Name AUL_INS_NOMBRE: AULA!$B$10:$D$10
Name FIT_PAGO_DNI: FITNESS!$T$10:$V$10
Name SAL_INS_DNI: SALON!$H$10:$I$10
Name FIT_INS_APELLIDO: FITNESS!$E$10:$G$10
Name SAL_PAGO_MP: SALON!$W$14:$Z$14
Name FIT_PAGO_MONTO: FITNESS!$W$12:$Z$12
Name SAL_INS_APELLIDO: SALON!$E$10:$G$10
Name FIT_PAGO_ESTADO: FITNESS!$T$14:$V$14
Name FIT_PAGO_NOMBRE: FITNESS!$W$10:$Z$10
Name FIT_INS_DESCUENTO: FITNESS!$E$12:$G$12
Name AUL_INS_CUOTA: AULA!$B$12:$D$12
Name FIT_INS_PROMO: FITNESS!$H$12:$J$12
Name FIT_INS_ENTRENADOR: FITNESS!$K$12:$O$12
Name AUL_PAGO_APELLIDO: AULA!$AA$10:$AD$10
Name AUL_PAGO_DNI: AULA!$T$10:$V$10
Name FIT_INS_DNI: FITNESS!$H$10:$I$10
Name SAL_INS_CUOTA: SALON!$B$12:$D$12
Name AUL_INS_DNI: AULA!$H$10:$I$10
Name SAL_INS_HORARIO: SALON!$P$12:$R$12
Name SAL_PAGO_ACTIVIDAD: SALON!$T$12:$V$12
Name AUL_PAGO_MP: AULA!$W$14:$Z$14
Name SAL_INS_MODALIDAD: SALON!$P$10:$R$10
Name SAL_INS_ACTIVIDAD: SALON!$M$10:$O$10
Name SAL_PAGO_APELLIDO: SALON!$AA$10:$AD$10
Name FIT_INS_ACTIVIDAD: FITNESS!$M$10:$O$10
Name AUL_PAGO_NOMBRE: AULA!$W$10:$Z$10
Name SAL_PAGO_NOMBRE: SALON!$W$10:$Z$10
Name AUL_INS_TEL: AULA!$J$10:$L$10
Name AUL_PAGO_ESTADO: AULA!$T$14:$V$14
Name FIT_INS_NOMBRE: FITNESS!$B$10:$D$10
Name AUL_INS_ACTIVIDAD: AULA!$M$10:$O$10
Name SAL_PAGO_MONTO: SALON!$AA$12:$AD$12
Name FIT_PAGO_MP: FITNESS!$W$14:$Z$14

Sheet DASHBOARD
C2: LOCAL 1 | J2: CANCHA FÚTBOL 5 | AE2: ESPACIO FITNESS | AQ2: SALÓN SUPERIOR | AY2: =TODAY() -> 46227 | BE2: CAPITAL | BJ2: +/- 30 DÍAS
AY3: =NOW() -> 46227.681 | BB3: =MONTH(TODAY()) -> 7 | BE3: ='ADMINISTRACIÓN'!AD12 -> 2498829 | BJ3: =IFERROR(SUMIFS('ADMINISTRACIÓN'!$U$13:$U$2003,'ADMINISTRACIÓN'!$E$13:$E$2003,"INGRESOS",'ADMINISTRACIÓN'!$C$13:$C$2003,">="&($AY$2-30),'ADMINISTRACIÓN'!$C$13:$C$2003,"<="&$AY$2)-SUMIFS('ADMINISTRACIÓN'!$U$13:$U$2003,'ADMINISTRACIÓN'!$E$13:$E$2003,"EGRESOS",'ADMINISTRACIÓN'!$C$13:$C$2003,">="&($AY$2-30),'ADMINISTRACIÓN'!$C$13:$C$2003,"<="&$AY$2),0) -> -546616
AY4: ------------------------------------------------------------------------------------
AY5: INGRESOS | BB5: JULIO | BG5: GASTOS | BK5: +/-
AY6: =IF(OR($BB$5="ENERO",$BB$5="MARZO",$BB$5="MAYO",$BB$5="JULIO",$BB$5="SEPTIEMBRE",$BB$5="NOVIEMBRE"),VLOOKUP($BB$5,'ADMINISTRACIÓN'!$B$3:$E$8,3,FALSE),VLOOKUP($BB$5,'ADMINISTRACIÓN'!$F3:$I8,3,FALSE)) -> 4967369 | BE6: =IF(OR($BB$5="ENERO",$BB$5="MARZO",$BB$5="MAYO",$BB$5="JULIO",$BB$5="SEPTIEMBRE",$BB$5="NOVIEMBRE"),VLOOKUP($BB$5,'ADMINISTRACIÓN'!$K$3:$N$8,3,FALSE),VLOOKUP($BB$5,'ADMINISTRACIÓN'!$O3:$R8,3,FALSE)) -> -5593840 | BK6: =AY6+BE6 -> -626471
AY8: $ LOCAL 1 | BD8: 0 | BL8: ESTADO
AY9: $ LOCAL 2 | BD9: 0 | BL9: ESTADO
C10: LOCAL 2 | AY10: $ CANCHA 1 | BD10: 0 | BL10: ESTADO
AY11: $ FITNESS | BD11: 0 | BL11: ESTADO
AY12: $ CANTINA | BD12: 0 | BL12: ESTADO
AY13: $ SALÓN | BD13: 0 | BL13: ESTADO
AY14: $ AULA | BD14: 0 | BL14: ESTADO
AY15: $ OTROS | BD15: 0 | BL15: ESTADO
AY16: $ TESORERÍA | BD16: 0 | BL16: ESTADO
F18: ADMINISTRACIÓN | U18: CANTINA | AA18: BAÑOS | AQ18: AULA SUPERIOR | AY18: ALQUILER | BC18: {=LET( mesTxt, LOWER(TRIM($BB$5)), meses, {"enero";"febrero";"marzo";"abril";"mayo";"junio";"julio";"agosto";"septiembre";"octubre";"noviembre";"diciembre"}, mesNum, IFERROR(MATCH(mesTxt, meses, 0), 0), anio, YEAR($AY$2), inicio, DATE(anio, mesNum, 1), finExcl, EDATE(inicio, 1), gasto, UPPER(TRIM(AY18)), existe, IF( mesNum=0, FALSE, COUNTIFS( 'ADMINISTRACIÓN'!$C$13:$C$2003, ">="&inicio, 'ADMINISTRACIÓN'!$C$13:$C$2003, "<"&finExcl, 'ADMINISTRACIÓN'!$H$13:$H$2003, gasto )>0 ), IF( mesNum=0, "MES INVÁLIDO", IF(existe, "PAGADO", IF(mesNum=$BB$3, "PENDIENTE", "IMPAGO")) ) )} -> PAGADO | BG18: LUZ | BK18: {=LET( mesTxt, LOWER(TRIM($BB$5)), meses, {"enero";"febrero";"marzo";"abril";"mayo";"junio";"julio";"agosto";"septiembre";"octubre";"noviembre";"diciembre"}, mesNum, IFERROR(MATCH(mesTxt, meses, 0), 0), anio, YEAR($AY$2), inicio, DATE(anio, mesNum, 1), finExcl, EDATE(inicio, 1), gasto, UPPER(TRIM(BG18)), existe, IF( mesNum=0, FALSE, COUNTIFS( 'ADMINISTRACIÓN'!$C$13:$C$2003, ">="&inicio, 'ADMINISTRACIÓN'!$C$13:$C$2003, "<"&finExcl, 'ADMINISTRACIÓN'!$H$13:$H$2003, gasto )>0 ), IF( mesNum=0, "MES INVÁLIDO", IF(existe, "PAGADO", IF(mesNum=$BB$3, "PENDIENTE", "IMPAGO")) ) )} -> PAGADO
AY19: AGUA | BC19: {=LET( mesTxt, LOWER(TRIM($BB$5)), meses, {"enero";"febrero";"marzo";"abril";"mayo";"junio";"julio";"agosto";"septiembre";"octubre";"noviembre";"diciembre"}, mesNum, IFERROR(MATCH(mesTxt, meses, 0), 0), anio, YEAR($AY$2), inicio, DATE(anio, mesNum, 1), finExcl, EDATE(inicio, 1), gasto, UPPER(TRIM(AY19)), existe, IF( mesNum=0, FALSE, COUNTIFS( 'ADMINISTRACIÓN'!$C$13:$C$2003, ">="&inicio, 'ADMINISTRACIÓN'!$C$13:$C$2003, "<"&finExcl, 'ADMINISTRACIÓN'!$H$13:$H$2003, gasto )>0 ), IF( mesNum=0, "MES INVÁLIDO", IF(existe, "PAGADO", IF(mesNum=$BB$3, "PENDIENTE", "IMPAGO")) ) )} -> PAGADO | BG19: INTERNET | BK19: {=LET( mesTxt, LOWER(TRIM($BB$5)), meses, {"enero";"febrero";"marzo";"abril";"mayo";"junio";"julio";"agosto";"septiembre";"octubre";"noviembre";"diciembre"}, mesNum, IFERROR(MATCH(mesTxt, meses, 0), 0), anio, YEAR($AY$2), inicio, DATE(anio, mesNum, 1), finExcl, EDATE(inicio, 1), gasto, UPPER(TRIM(BG19)), existe, IF( mesNum=0, FALSE, COUNTIFS( 'ADMINISTRACIÓN'!$C$13:$C$2003, ">="&inicio, 'ADMINISTRACIÓN'!$C$13:$C$2003, "<"&finExcl, 'ADMINISTRACIÓN'!$H$13:$H$2003, gasto )>0 ), IF( mesNum=0, "MES INVÁLIDO", IF(existe, "PAGADO", IF(mesNum=$BB$3, "PENDIENTE", "IMPAGO")) ) )} -> PAGADO
AY20: IMPUESTOS | BC20: {=LET( mesTxt, LOWER(TRIM($BB$5)), meses, {"enero";"febrero";"marzo";"abril";"mayo";"junio";"julio";"agosto";"septiembre";"octubre";"noviembre";"diciembre"}, mesNum, IFERROR(MATCH(mesTxt, meses, 0), 0), anio, YEAR($AY$2), inicio, DATE(anio, mesNum, 1), finExcl, EDATE(inicio, 1), gasto, UPPER(TRIM(AY20)), existe, IF( mesNum=0, FALSE, COUNTIFS( 'ADMINISTRACIÓN'!$C$13:$C$2003, ">="&inicio, 'ADMINISTRACIÓN'!$C$13:$C$2003, "<"&finExcl, 'ADMINISTRACIÓN'!$H$13:$H$2003, gasto )>0 ), IF( mesNum=0, "MES INVÁLIDO", IF(existe, "PAGADO", IF(mesNum=$BB$3, "PENDIENTE", "IMPAGO")) ) )} -> PAGADO | BG20: SALARIOS | BK20: {=LET( mesTxt, LOWER(TRIM($BB$5)), meses, {"enero";"febrero";"marzo";"abril";"mayo";"junio";"julio";"agosto";"septiembre";"octubre";"noviembre";"diciembre"}, mesNum, IFERROR(MATCH(mesTxt, meses, 0), 0), anio, YEAR($AY$2), inicio, DATE(anio, mesNum, 1), finExcl, EDATE(inicio, 1), gasto, UPPER(TRIM(BG20)), existe, IF( mesNum=0, FALSE, COUNTIFS( 'ADMINISTRACIÓN'!$C$13:$C$2003, ">="&inicio, 'ADMINISTRACIÓN'!$C$13:$C$2003, "<"&finExcl, 'ADMINISTRACIÓN'!$H$13:$H$2003, gasto )>0 ), IF( mesNum=0, "MES INVÁLIDO", IF(existe, "PAGADO", IF(mesNum=$BB$3, "PENDIENTE", "IMPAGO")) ) )} -> PENDIENTE
AY22: SECTOR +++ | BD22: SECTOR ---

Sheet ADMINISTRACIÓN
B2: INGRESOS | K2: GASTOS | T2: UTILIDAD | AD2: AGREGAR MOVIMIENTO
B3: Enero | D3: =SUMIFS($U$13:$U$2004,$C$13:$C$2004,">="&DATE(2026,1,1),$C$13:$C$2004,"<"&DATE(2026,2,1),$E$13:$E$2004,"INGRESOS",$Z$13:$Z$2004,"COMPLETADO") -> 0 | F3: Febrero | H3: =SUMIFS($U$13:$U$2004,$C$13:$C$2004,">="&DATE(2026,2,1),$C$13:$C$2004,"<"&DATE(2026,3,1),$E$13:$E$2004,"INGRESOS",$Z$13:$Z$2004,"COMPLETADO") -> 0 | K3: Enero | M3: =-(SUMIFS($U$13:$U$2004,$C$13:$C$2004,">="&DATE(2026,1,1),$C$13:$C$2004,"<"&DATE(2026,2,1),$E$13:$E$2004,"EGRESOS",$Z$13:$Z$2004,"COMPLETADO") -SUMIFS($U$13:$U$2004,$C$13:$C$2004,">="&DATE(2026,1,1),$C$13:$C$2004,"<"&DATE(2026,2,1),$E$13:$E$2004,"EGRESOS",$H$13:$H$2004,"DÓLARES",$Z$13:$Z$2004,"COMPLETADO")) -> 0 | O3: Febrero | Q3: =-(SUMIFS($U$13:$U$2004,$C$13:$C$2004,">="&DATE(2026,2,1),$C$13:$C$2004,"<"&DATE(2026,3,1),$E$13:$E$2004,"EGRESOS",$Z$13:$Z$2004,"COMPLETADO") -SUMIFS($U$13:$U$2004,$C$13:$C$2004,">="&DATE(2026,2,1),$C$13:$C$2004,"<"&DATE(2026,3,1),$E$13:$E$2004,"EGRESOS",$H$13:$H$2004,"DÓLARES",$Z$13:$Z$2004,"COMPLETADO")) -> -100000 | T3: Enero | V3: =D3+M3 -> 0 | X3: Febrero | Z3: =H3+Q3 -> -100000 | AD3: Tipo | AF3: Categ. | AI3: Sector
B4: Marzo | D4: =SUMIFS($U$13:$U$2004,$C$13:$C$2004,">="&DATE(2026,3,1),$C$13:$C$2004,"<"&DATE(2026,4,1),$E$13:$E$2004,"INGRESOS",$Z$13:$Z$2004,"COMPLETADO") -> 1083501 | F4: Abril | H4: =SUMIFS($U$13:$U$2004,$C$13:$C$2004,">="&DATE(2026,4,1),$C$13:$C$2004,"<"&DATE(2026,5,1),$E$13:$E$2004,"INGRESOS",$Z$13:$Z$2004,"COMPLETADO") -> 4289262 | K4: Marzo | M4: =-(SUMIFS($U$13:$U$2004,$C$13:$C$2004,">="&DATE(2026,3,1),$C$13:$C$2004,"<"&DATE(2026,4,1),$E$13:$E$2004,"EGRESOS",$Z$13:$Z$2004,"COMPLETADO") -SUMIFS($U$13:$U$2004,$C$13:$C$2004,">="&DATE(2026,3,1),$C$13:$C$2004,"<"&DATE(2026,4,1),$E$13:$E$2004,"EGRESOS",$H$13:$H$2004,"DÓLARES",$Z$13:$Z$2004,"COMPLETADO")) -> -11319563 | O4: Abril | Q4: =-(SUMIFS($U$13:$U$2004,$C$13:$C$2004,">="&DATE(2026,4,1),$C$13:$C$2004,"<"&DATE(2026,5,1),$E$13:$E$2004,"EGRESOS",$Z$13:$Z$2004,"COMPLETADO") -SUMIFS($U$13:$U$2004,$C$13:$C$2004,">="&DATE(2026,4,1),$C$13:$C$2004,"<"&DATE(2026,5,1),$E$13:$E$2004,"EGRESOS",$H$13:$H$2004,"DÓLARES",$Z$13:$Z$2004,"COMPLETADO")) -> -5157136 | T4: Marzo | V4: =D4+M4 -> -10236062 | X4: Abril | Z4: =H4+Q4 -> -867874
B5: Mayo | D5: =SUMIFS($U$13:$U$2004,$C$13:$C$2004,">="&DATE(2026,5,1),$C$13:$C$2004,"<"&DATE(2026,6,1),$E$13:$E$2004,"INGRESOS",$Z$13:$Z$2004,"COMPLETADO") -> 4296109 | F5: Junio | H5: =SUMIFS($U$13:$U$2004,$C$13:$C$2004,">="&DATE(2026,6,1),$C$13:$C$2004,"<"&DATE(2026,7,1),$E$13:$E$2004,"INGRESOS",$Z$13:$Z$2004,"COMPLETADO") -> 5622517 | K5: Mayo | M5: =-(SUMIFS($U$13:$U$2004,$C$13:$C$2004,">="&DATE(2026,5,1),$C$13:$C$2004,"<"&DATE(2026,6,1),$E$13:$E$2004,"EGRESOS",$Z$13:$Z$2004,"COMPLETADO") -SUMIFS($U$13:$U$2004,$C$13:$C$2004,">="&DATE(2026,5,1),$C$13:$C$2004,"<"&DATE(2026,6,1),$E$13:$E$2004,"EGRESOS",$H$13:$H$2004,"DÓLARES",$Z$13:$Z$2004,"COMPLETADO")) -> -4714283 | O5: Junio | Q5: =-(SUMIFS($U$13:$U$2004,$C$13:$C$2004,">="&DATE(2026,6,1),$C$13:$C$2004,"<"&DATE(2026,7,1),$E$13:$E$2004,"EGRESOS",$Z$13:$Z$2004,"COMPLETADO") -SUMIFS($U$13:$U$2004,$C$13:$C$2004,">="&DATE(2026,6,1),$C$13:$C$2004,"<"&DATE(2026,7,1),$E$13:$E$2004,"EGRESOS",$H$13:$H$2004,"DÓLARES",$Z$13:$Z$2004,"COMPLETADO")) -> -5626507 | T5: Mayo | V5: =D5+M5 -> -418174 | X5: Junio | Z5: =H5+Q5 -> -3990 | AD5: Concepto | AH5: Monto $
B6: Julio | D6: =SUMIFS($U$13:$U$2004,$C$13:$C$2004,">="&DATE(2026,7,1),$C$13:$C$2004,"<"&DATE(2026,8,1),$E$13:$E$2004,"INGRESOS",$Z$13:$Z$2004,"COMPLETADO") -> 4967369 | F6: Agosto | H6: =SUMIFS($U$13:$U$2004,$C$13:$C$2004,">="&DATE(2026,8,1),$C$13:$C$2004,"<"&DATE(2026,9,1),$E$13:$E$2004,"INGRESOS",$Z$13:$Z$2004,"COMPLETADO") -> 0 | K6: Julio | M6: =-(SUMIFS($U$13:$U$2004,$C$13:$C$2004,">="&DATE(2026,7,1),$C$13:$C$2004,"<"&DATE(2026,8,1),$E$13:$E$2004,"EGRESOS",$Z$13:$Z$2004,"COMPLETADO") -SUMIFS($U$13:$U$2004,$C$13:$C$2004,">="&DATE(2026,7,1),$C$13:$C$2004,"<"&DATE(2026,8,1),$E$13:$E$2004,"EGRESOS",$H$13:$H$2004,"DÓLARES",$Z$13:$Z$2004,"COMPLETADO")) -> -5593840 | O6: Agosto | Q6: =-(SUMIFS($U$13:$U$2004,$C$13:$C$2004,">="&DATE(2026,8,1),$C$13:$C$2004,"<"&DATE(2026,9,1),$E$13:$E$2004,"EGRESOS",$Z$13:$Z$2004,"COMPLETADO") -SUMIFS($U$13:$U$2004,$C$13:$C$2004,">="&DATE(2026,8,1),$C$13:$C$2004,"<"&DATE(2026,9,1),$E$13:$E$2004,"EGRESOS",$H$13:$H$2004,"DÓLARES",$Z$13:$Z$2004,"COMPLETADO")) -> 0 | T6: Julio | V6: =D6+M6 -> -626471 | X6: Agosto | Z6: =H6+Q6 -> 0
B7: Septiembre | D7: =SUMIFS($U$13:$U$2004,$C$13:$C$2004,">="&DATE(2026,9,1),$C$13:$C$2004,"<"&DATE(2026,10,1),$E$13:$E$2004,"INGRESOS",$Z$13:$Z$2004,"COMPLETADO") -> 0 | F7: Octubre | H7: =SUMIFS($U$13:$U$2004,$C$13:$C$2004,">="&DATE(2026,10,1),$C$13:$C$2004,"<"&DATE(2026,11,1),$E$13:$E$2004,"INGRESOS",$Z$13:$Z$2004,"COMPLETADO") -> 0 | K7: Septiembre | M7: =-(SUMIFS($U$13:$U$2004,$C$13:$C$2004,">="&DATE(2026,9,1),$C$13:$C$2004,"<"&DATE(2026,10,1),$E$13:$E$2004,"EGRESOS",$Z$13:$Z$2004,"COMPLETADO") -SUMIFS($U$13:$U$2004,$C$13:$C$2004,">="&DATE(2026,9,1),$C$13:$C$2004,"<"&DATE(2026,10,1),$E$13:$E$2004,"EGRESOS",$H$13:$H$2004,"DÓLARES",$Z$13:$Z$2004,"COMPLETADO")) -> 0 | O7: Octubre | Q7: =-(SUMIFS($U$13:$U$2004,$C$13:$C$2004,">="&DATE(2026,10,1),$C$13:$C$2004,"<"&DATE(2026,11,1),$E$13:$E$2004,"EGRESOS",$Z$13:$Z$2004,"COMPLETADO") -SUMIFS($U$13:$U$2004,$C$13:$C$2004,">="&DATE(2026,4,1),$C$13:$C$2004,"<"&DATE(2026,5,1),$E$13:$E$2004,"EGRESOS",$H$13:$H$2004,"DÓLARES",$Z$13:$Z$2004,"COMPLETADO")) -> 0 | T7: Septiembre | V7: =D7+M7 -> 0 | X7: Octubre | Z7: =H7+Q7 -> 0 | AD7: Contra-parte (D.N.I.)
B8: Noviembre | D8: =SUMIFS($U$13:$U$2004,$C$13:$C$2004,">="&DATE(2026,11,1),$C$13:$C$2004,"<"&DATE(2026,12,1),$E$13:$E$2004,"INGRESOS",$Z$13:$Z$2004,"COMPLETADO") -> 0 | F8: Diciembre | H8: =SUMIFS($U$13:$U$2004,$C$13:$C$2004,">="&DATE(2026,12,1),$C$13:$C$2004,"<"&DATE(2027,1,1),$E$13:$E$2004,"INGRESOS",$Z$13:$Z$2004,"COMPLETADO") -> 0 | K8: Noviembre | M8: =-(SUMIFS($U$13:$U$2004,$C$13:$C$2004,">="&DATE(2026,11,1),$C$13:$C$2004,"<"&DATE(2026,12,1),$E$13:$E$2004,"EGRESOS",$Z$13:$Z$2004,"COMPLETADO") -SUMIFS($U$13:$U$2004,$C$13:$C$2004,">="&DATE(2026,4,1),$C$13:$C$2004,"<"&DATE(2026,5,1),$E$13:$E$2004,"EGRESOS",$H$13:$H$2004,"DÓLARES",$Z$13:$Z$2004,"COMPLETADO")) -> 0 | O8: Diciembre | Q8: =-(SUMIFS($U$13:$U$2004,$C$13:$C$2004,">="&DATE(2026,12,1),$C$13:$C$2004,"<"&DATE(2027,1,1),$E$13:$E$2004,"EGRESOS",$Z$13:$Z$2004,"COMPLETADO") -SUMIFS($U$13:$U$2004,$C$13:$C$2004,">="&DATE(2026,4,1),$C$13:$C$2004,"<"&DATE(2026,5,1),$E$13:$E$2004,"EGRESOS",$H$13:$H$2004,"DÓLARES",$Z$13:$Z$2004,"COMPLETADO")) -> 0 | T8: Noviembre | V8: =D8+M8 -> 0 | X8: Diciembre | Z8: =H8+Q8 -> 0 | AD8: Impuesto | AF8: 0 | AG8: M.P.
B9: TOTAL | F9: =SUM(D3:E8,H3:I8) -> 20258758 | K9: TOTAL | O9: =SUM(M3:N8,Q3:R8) -> -32511329 | T9: TOTAL | X9: =SUM(V3:W8,Z3:AA8) -> -12252571 | AD9: AGREGAR
B11: MOVIMIENTOS | AD11: CAJA Y BANCOS
B12: Id. | C12: Fecha | E12: Tipo | H12: Categoría | K12: Concepto | P12: Contra-parte | S12: Sector | U12: Monto | X12: Impuestos | Z12: Estado | AB12: M.P. | AD12: =SUMIFS($U$13:$U$2004,$E$13:$E$2004,"CAPITAL",$Z$13:$Z$2004,"COMPLETADO")-SUMIFS($U$13:$U$2004,$E$13:$E$2004,"CAPITAL",$H$13:$H$2004,"DÓLARES",$Z$13:$Z$2004,"COMPLETADO")+X9+(AG14*AF14) -> 2498829 | AG12: =SUMIFS($U$13:$U$2004,$E$13:$E$2004,"INGRESOS",$AB$13:$AB$2004,"Efectivo",$Z$13:$Z$2004,"COMPLETADO")+SUMIFS($U$13:$U$2004,$E$13:$E$2004,"CAPITAL",$AB$13:$AB$2004,"Efectivo",$Z$13:$Z$2004,"COMPLETADO")-SUMIFS($U$13:$U$2004,$E$13:$E$2004,"EGRESOS",$AB$13:$AB$2004,"Efectivo",$Z$13:$Z$2004,"COMPLETADO") -> 1812430 | AI12: Efectivo | AK12: PROYECTADO
B13: I-1038 | C13: 46227.655 | E13: INGRESOS | H13: CUOTA | K13: Pago de cuota [F-0027] de Patricia Feldick por actividad de Funcional | P13: 20.118.913 | S13: FITNESS | U13: 0 | X13: 0 | Z13: COMPLETADO | AB13: Efectivo | AG13: =SUMIFS($U$13:$U$2004,$E$13:$E$2004,"INGRESOS",$AB$13:$AB$2004,"Transferencia",$Z$13:$Z$2004,"COMPLETADO")+SUMIFS($U$13:$U$2004,$E$13:$E$2004,"CAPITAL",$AB$13:$AB$2004,"Transferencia",$Z$13:$Z$2004,"COMPLETADO")-SUMIFS($U$13:$U$2004,$E$13:$E$2004,"EGRESOS",$AB$13:$AB$2004,"Transferencia",$Z$13:$Z$2004,"COMPLETADO") -> 535399 | AI13: Cuenta Corriente | AK13: =$AD$12+SUMIFS($U$13:$U$2004,$E$13:$E$2004,"INGRESOS",$Z$13:$Z$2004,"PENDIENTE")-SUMIFS($U$13:$U$2004,$E$13:$E$2004,"EGRESOS",$Z$13:$Z$2004,"PENDIENTE")+($AF$14*(SUMIFS($U$13:$U$2004,$H$13:$H$2004,"DÓLARES",$Z$13:$Z$2004,"PENDIENTE")))-'LOCAL 1'!X3-FITNESS!X3-SALON!AB19-AULA!AB19 -> 1711829
B14: E-1037 | C14: 46226.954 | E14: EGRESOS | H14: IMPUESTOS | K14: Retención IIBB SIRCUPA | P14: 67.238.712 | S14: TESORERÍA | U14: 3000 | X14: 0 | Z14: COMPLETADO | AB14: Transferencia | AD14: Tipo de cambio → | AF14: 1510 | AG14: =SUMIFS($U$13:$U$2004,$E$13:$E$2004,"INGRESOS",$H$13:$H$2004,"DÓLARES",$Z$13:$Z$2004,"COMPLETADO")+SUMIFS($U$13:$U$2004,$E$13:$E$2004,"CAPITAL",$H$13:$H$2004,"DÓLARES",$Z$13:$Z$2004,"COMPLETADO")-SUMIFS($U$13:$U$2004,$E$13:$E$2004,"EGRESOS",$H$13:$H$2004,"DÓLARES",$Z$13:$Z$2004,"COMPLETADO") -> 100 | AI14: Dólares
B15: I-1036 | C15: 46226.844 | E15: INGRESOS | H15: VENTAS | K15: Seña Tattoo - Minitattoo Silvina | P15: 35.872.158 | S15: LOCAL 1 | U15: 20000 | X15: 0 | Z15: COMPLETADO | AB15: Transferencia
B16: I-1035 | C16: 46226.842 | E16: INGRESOS | H16: VENTAS | K16: Seña Tattoo - Mundialista Pamela | P16: 35.872.158 | S16: LOCAL 1 | U16: 40000 | X16: 0 | Z16: COMPLETADO | AB16: Transferencia | AD16: INFO SECTORES
B17: E-1034 | C17: 46226.7 | E17: EGRESOS | H17: EXTRACCIONES | K17: Conciliación de caja y banco - contra I-1033 | P17: 35.004.264 | S17: TESORERÍA | U17: 20000 | X17: 0 | Z17: COMPLETADO | AB17: Transferencia | AD17: SECTOR | AF17: INGRESOS | AH17: EGRESOS | AJ17: VOL. | AK17: UTILIDAD
B18: I-1033 | C18: 46226.698 | E18: INGRESOS | H18: DEPÓSITOS | K18: Conciliación de caja y banco - contra E-1034 | P18: 35.004.264 | S18: TESORERÍA | U18: 20000 | X18: 0 | Z18: COMPLETADO | AB18: Efectivo | AD18: LOCAL 1 | AF18: =SUMIFS($U$13:$U$2004,$S$13:$S$2004,AD18,$E$13:$E$2004,$AF$17,$Z13:$Z2004,"COMPLETADO") -> 6734800 | AH18: =SUMIFS($U$13:$U$2004,$S$13:$S$2004,AD18,$E$13:$E$2004,$AH$17,$Z13:$Z2004,"COMPLETADO")*-1 -> -3657365 | AJ18: =COUNTIF($S$13:$S$2004,AD18) -> 163 | AK18: =AF18+AH18 -> 3077435
B19: E-1032 | C19: 46226.591 | E19: EGRESOS | H19: COMISIÓN | K19: Pago de SALDO A LIQUIDAR - 23/7/2026 | P19: 35.872.158 | S19: LOCAL 1 | U19: 45000 | X19: 0 | Z19: COMPLETADO | AB19: Transferencia | AD19: LOCAL 2 | AF19: =SUMIFS($U$13:$U$2004,$S$13:$S$2004,AD19,$E$13:$E$2004,$AF$17,$Z13:$Z2004,"COMPLETADO") -> 0 | AH19: =SUMIFS($U$13:$U$2004,$S$13:$S$2004,AD19,$E$13:$E$2004,$AH$17,$Z13:$Z2004,"COMPLETADO")*-1 -> -88825 | AJ19: =COUNTIF($S$13:$S$2004,AD19) -> 3 | AK19: =AF19+AH19 -> -88825
B20: I-1031 | C20: 46226.59 | E20: INGRESOS | H20: VENTAS | K20: Seña Tattoo - minitattoos en la mano Virginia | P20: 35.872.158 | S20: LOCAL 1 | U20: 30000 | X20: 0 | Z20: COMPLETADO | AB20: Transferencia | AD20: CANCHA 1 | AF20: =SUMIFS($U$13:$U$2004,$S$13:$S$2004,AD20,$E$13:$E$2004,$AF$17,$Z13:$Z2004,"COMPLETADO") -> 0 | AH20: =SUMIFS($U$13:$U$2004,$S$13:$S$2004,AD20,$E$13:$E$2004,$AH$17,$Z13:$Z2004,"COMPLETADO")*-1 -> -100000 | AJ20: =COUNTIF($S$13:$S$2004,AD20) -> 1 | AK20: =AF20+AH20 -> -100000
B21: E-1030 | C21: 46226.588 | E21: EGRESOS | H21: LIMPIEZA | K21: Papel Higiénico + naftalina + lavandina + trapos | P21: 24.600.903 | S21: OTROS | U21: 34800 | X21: 0 | Z21: COMPLETADO | AB21: Transferencia | AD21: FITNESS | AF21: =SUMIFS($U$13:$U$2004,$S$13:$S$2004,AD21,$E$13:$E$2004,$AF$17,$Z13:$Z2004,"COMPLETADO") -> 8025500 | AH21: =SUMIFS($U$13:$U$2004,$S$13:$S$2004,AD21,$E$13:$E$2004,$AH$17,$Z13:$Z2004,"COMPLETADO")*-1 -> -4147367 | AJ21: =COUNTIF($S$13:$S$2004,AD21) -> 315 | AK21: =AF21+AH21 -> 3878133
B22: E-1029 | C22: 46226.536 | E22: EGRESOS | H22: AGUA | K22: SAMSA - Período 6/26 - 38mts cúbicos | P22: 69.809.590 | S22: OTROS | U22: 177442 | X22: 0 | Z22: COMPLETADO | AB22: Transferencia | AD22: CANTINA | AF22: =SUMIFS($U$13:$U$2004,$S$13:$S$2004,AD22,$E$13:$E$2004,$AF$17,$Z13:$Z2004,"COMPLETADO") -> 763017 | AH22: =SUMIFS($U$13:$U$2004,$S$13:$S$2004,AD22,$E$13:$E$2004,$AH$17,$Z13:$Z2004,"COMPLETADO")*-1 -> -1660925 | AJ22: =COUNTIF($S$13:$S$2004,AD22) -> 63 | AK22: =AF22+AH22 -> -897908
B23: I-1028 | C23: 46225.829 | E23: INGRESOS | H23: CUOTA | K23: Pago de cuota [F-0018] de Silvina Molina por actividad de Funcional | P23: 33.720.939 | S23: FITNESS | U23: 30000 | X23: 0 | Z23: COMPLETADO | AB23: Transferencia | AD23: SALON | AF23: =SUMIFS($U$13:$U$2004,$S$13:$S$2004,AD23,$E$13:$E$2004,$AF$17,$Z13:$Z2004,"COMPLETADO") -> 2527500 | AH23: =SUMIFS($U$13:$U$2004,$S$13:$S$2004,AD23,$E$13:$E$2004,$AH$17,$Z13:$Z2004,"COMPLETADO")*-1 -> -1227050 | AJ23: =COUNTIF($S$13:$S$2004,AD23) -> 131 | AK23: =AF23+AH23 -> 1300450
B24: E-1027 | C24: 46225.741 | E24: EGRESOS | H24: IMPUESTOS | K24: Retención IIBB SIRCUPA | P24: 67.238.712 | S24: TESORERÍA | U24: 4850 | X24: 0 | Z24: COMPLETADO | AB24: Transferencia | AD24: AULA | AF24: =SUMIFS($U$13:$U$2004,$S$13:$S$2004,AD24,$E$13:$E$2004,$AF$17,$Z13:$Z2004,"COMPLETADO") -> 835000 | AH24: =SUMIFS($U$13:$U$2004,$S$13:$S$2004,AD24,$E$13:$E$2004,$AH$17,$Z13:$Z2004,"COMPLETADO")*-1 -> -497000 | AJ24: =COUNTIF($S$13:$S$2004,AD24) -> 52 | AK24: =AF24+AH24 -> 338000
B25: I-1026 | C25: 46225.71 | E25: INGRESOS | H25: CUOTA | K25: Pago de cuota [C-0139] de Cristian Gimenez por actividad de Complemento | P25: 33.486.350 | S25: FITNESS | U25: 30000 | X25: 0 | Z25: COMPLETADO | AB25: Transferencia | AD25: TESORERÍA | AF25: =SUMIFS($U$13:$U$2004,$S$13:$S$2004,AD25,$E$13:$E$2004,$AF$17)+SUMIFS($U$13:$U$2004,$S$13:$S$2004,AD25,$E$13:$E$2004,"CAPITAL",$U$13:$U$2004,">0",$Z13:$Z2004,"COMPLETADO") -> 16124841 | AH25: =(SUMIFS($U$13:$U$2004,$S$13:$S$2004,AD25,$E$13:$E$2004,$AH$17)*-1)+SUMIFS($U$13:$U$2004,$S$13:$S$2004,AD25,$E$13:$E$2004,"CAPITAL",$U$13:$U$2004,"<0",$Z13:$Z2004,"COMPLETADO") -> -16416451 | AJ25: =COUNTIF($S$13:$S$2004,AD25) -> 222 | AK25: =AF25+AH25 -> -291610
B26: I-1025 | C26: 46225.708 | E26: INGRESOS | H26: CUOTA | K26: Pago de cuota [C-0138] de Daniela Soto por actividad de Complemento | P26: 32.608.369 | S26: FITNESS | U26: 30000 | X26: 0 | Z26: COMPLETADO | AB26: Transferencia | AD26: OTROS | AF26: =SUMIFS($U$13:$U$2004,$S$13:$S$2004,AD26,$E$13:$E$2004,$AF$17,$Z13:$Z2004,"COMPLETADO") -> 0 | AH26: =SUMIFS($U$13:$U$2004,$S$13:$S$2004,AD26,$E$13:$E$2004,$AH$17,$Z13:$Z2004,"COMPLETADO")*-1 -> -4883846 | AJ26: =COUNTIF($S$13:$S$2004,AD26) -> 88 | AK26: =AF26+AH26 -> -4883846
B27: E-1024 | C27: 46225.704 | E27: EGRESOS | H27: COMISIÓN | K27: Pago de SALDO A LIQUIDAR - 22/7/2026 | P27: 35.872.158 | S27: LOCAL 1 | U27: 150000 | X27: 0 | Z27: COMPLETADO | AB27: Efectivo
B28: I-1023 | C28: 46225.702 | E28: INGRESOS | H28: VENTAS | K28: Tattoo - Manga floral Isabel | P28: 35.872.158 | S28: LOCAL 1 | U28: 300000 | X28: 0 | Z28: COMPLETADO | AB28: Efectivo | AD28: INFO CATEGORÍAS
B29: E-1022 | C29: 46225.699 | E29: EGRESOS | H29: COMISIÓN | K29: Pago de SALDO A LIQUIDAR - 22/7/2026 | P29: 35.872.158 | S29: LOCAL 1 | U29: 25000 | X29: 0 | Z29: COMPLETADO | AB29: Transferencia | AD29: CATEG. | AF29: INGRESOS | AH29: EGRESOS | AJ29: VOL. | AK29: UTILIDAD
B30: I-1021 | C30: 46225.697 | E30: INGRESOS | H30: VENTAS | K30: Seña Tattoo - Proyecto cobertura cicatrices Paula | P30: 35.872.158 | S30: LOCAL 1 | U30: 50000 | X30: 0 | Z30: COMPLETADO | AB30: Transferencia | AD30: INSCRIPCIÓN | AF30: =SUMIFS($U$13:$U$2004,$H$13:$H$2004,AD30,$E$13:$E$2004,$AF$29) -> 0 | AH30: =SUMIFS($U$13:$U$2004,$H$13:$H$2004,AD30,$E$13:$E$2004,$AH$29,$Z13:$Z2004,"COMPLETADO")*-1 -> 0 | AJ30: =COUNTIF($H$13:$H$2004,AD30) -> 0 | AK30: =AF30+AH30 -> 0
B31: I-1020 | C31: 46224.925 | E31: INGRESOS | H31: CUOTA | K31: Pago de cuota [K-0075] de Ginna Caruso por clases de Kickboxing al profesor Natalia Ortiz | P31: 37.704.699 | S31: SALON | U31: 20000 | X31: 0 | Z31: COMPLETADO | AB31: Efectivo | AD31: CUOTA | AF31: =SUMIFS($U$13:$U$2004,$H$13:$H$2004,AD31,$E$13:$E$2004,$AF$29) -> 10629500 | AH31: =SUMIFS($U$13:$U$2004,$H$13:$H$2004,AD31,$E$13:$E$2004,$AH$29,$Z13:$Z2004,"COMPLETADO")*-1 -> -75000 | AJ31: =COUNTIF($H$13:$H$2004,AD31) -> 424 | AK31: =AF31+AH31 -> 10554500
B32: I-1019 | C32: 46224.899 | E32: INGRESOS | H32: CUOTA | K32: Pago de cuota [F-0042] de Carolina Paredes por actividad de Funcional | P32: 28.162.967 | S32: FITNESS | U32: 6000 | X32: 0 | Z32: COMPLETADO | AB32: Transferencia | AD32: TURNOS | AF32: =SUMIFS($U$13:$U$2004,$H$13:$H$2004,AD32,$E$13:$E$2004,$AF$29) -> 0 | AH32: =SUMIFS($U$13:$U$2004,$H$13:$H$2004,AD32,$E$13:$E$2004,$AH$29,$Z13:$Z2004,"COMPLETADO")*-1 -> 0 | AJ32: =COUNTIF($H$13:$H$2004,AD32) -> 0 | AK32: =AF32+AH32 -> 0
B33: E-1018 | C33: 46224.652 | E33: EGRESOS | H33: PUBLICIDAD | K33: Panfletos x300 + planillas de inscripción | P33: 00.000.000 | S33: OTROS | U33: 14000 | X33: 0 | Z33: COMPLETADO | AB33: Transferencia | AD33: COMISIÓN | AF33: =SUMIFS($U$13:$U$2004,$H$13:$H$2004,AD33,$E$13:$E$2004,$AF$29) -> 859000 | AH33: =SUMIFS($U$13:$U$2004,$H$13:$H$2004,AD33,$E$13:$E$2004,$AH$29,$Z13:$Z2004,"COMPLETADO")*-1 -> -6714900 | AJ33: =COUNTIF($H$13:$H$2004,AD33) -> 109 | AK33: =AF33+AH33 -> -5855900
B34: E-1017 | C34: 46224.631 | E34: EGRESOS | H34: PÉRDIDA | K34: Conciliación de caja y banco - Faltante | P34: 35.004.264 | S34: TESORERÍA | U34: 10000 | X34: 0 | Z34: COMPLETADO | AB34: Efectivo | AD34: ALQUILER | AF34: =SUMIFS($U$13:$U$2004,$H$13:$H$2004,AD34,$E$13:$E$2004,$AF$29) -> 115000 | AH34: =SUMIFS($U$13:$U$2004,$H$13:$H$2004,AD34,$E$13:$E$2004,$AH$29,$Z13:$Z2004,"COMPLETADO")*-1 -> -11260000 | AJ34: =COUNTIF($H$13:$H$2004,AD34) -> 11 | AK34: =AF34+AH34 -> -11145000
B35: E-1016 | C35: 46224.503 | E35: EGRESOS | H35: EXTRACCIONES | K35: Conciliación de caja y banco - contra I-1016 | P35: 35.004.264 | S35: TESORERÍA | U35: 40000 | X35: 0 | Z35: COMPLETADO | AB35: Transferencia | AD35: EVENTOS | AF35: =SUMIFS($U$13:$U$2004,$H$13:$H$2004,AD35,$E$13:$E$2004,$AF$29) -> 205000 | AH35: =SUMIFS($U$13:$U$2004,$H$13:$H$2004,AD35,$E$13:$E$2004,$AH$29,$Z13:$Z2004,"COMPLETADO")*-1 -> -59637 | AJ35: =COUNTIF($H$13:$H$2004,AD35) -> 6 | AK35: =AF35+AH35 -> 145363
B36: I-1015 | C36: 46224.494 | E36: INGRESOS | H36: DEPÓSITOS | K36: Conciliación de caja y banco - contra E-1017 | P36: 35.004.264 | S36: TESORERÍA | U36: 40000 | X36: 0 | Z36: COMPLETADO | AB36: Efectivo | AD36: VENTAS | AF36: =SUMIFS($U$13:$U$2004,$H$13:$H$2004,AD36,$E$13:$E$2004,$AF$29) -> 6115800 | AH36: =SUMIFS($U$13:$U$2004,$H$13:$H$2004,AD36,$E$13:$E$2004,$AH$29,$Z13:$Z2004,"COMPLETADO")*-1 -> 0 | AJ36: =COUNTIF($H$13:$H$2004,AD36) -> 76 | AK36: =AF36+AH36 -> 6115800
B37: I-1014 | C37: 46223.732 | E37: INGRESOS | H37: CUOTA | K37: Pago de cuota [C-0136] de Walter Segovia por actividad de Complemento | P37: 20.060.193 | S37: FITNESS | U37: 30000 | X37: 0 | Z37: COMPLETADO | AB37: Transferencia | AD37: CLASES | AF37: =SUMIFS($U$13:$U$2004,$H$13:$H$2004,AD37,$E$13:$E$2004,$AF$29) -> 0 | AH37: =SUMIFS($U$13:$U$2004,$H$13:$H$2004,AD37,$E$13:$E$2004,$AH$29,$Z13:$Z2004,"COMPLETADO")*-1 -> 0 | AJ37: =COUNTIF($H$13:$H$2004,AD37) -> 0 | AK37: =AF37+AH37 -> 0
B38: I-1013 | C38: 46223.7 | E38: INGRESOS | H38: CUOTA | K38: Pago de cuota [K-0064] de Javier Agustin Caceres Velazquez por clases de Karate al profesor Sergio Tabossi | P38: 54.376.352 | S38: SALON | U38: 20000 | X38: 0 | Z38: COMPLETADO | AB38: Efectivo | AD38: CURSOS | AF38: =SUMIFS($U$13:$U$2004,$H$13:$H$2004,AD38,$E$13:$E$2004,$AF$29) -> 0 | AH38: =SUMIFS($U$13:$U$2004,$H$13:$H$2004,AD38,$E$13:$E$2004,$AH$29,$Z13:$Z2004,"COMPLETADO")*-1 -> 0 | AJ38: =COUNTIF($H$13:$H$2004,AD38) -> 0 | AK38: =AF38+AH38 -> 0
B39: E-1012 | C39: 46223.681 | E39: EGRESOS | H39: VIÁTICOS | K39: Almuerzo | P39: 35.004.264 | S39: TESORERÍA | U39: 6200 | X39: 0 | Z39: COMPLETADO | AB39: Efectivo | AD39: PUBLICIDAD | AF39: =SUMIFS($U$13:$U$2004,$H$13:$H$2004,AD39,$E$13:$E$2004,$AF$29) -> 0 | AH39: =SUMIFS($U$13:$U$2004,$H$13:$H$2004,AD39,$E$13:$E$2004,$AH$29,$Z13:$Z2004,"COMPLETADO")*-1 -> -260000 | AJ39: =COUNTIF($H$13:$H$2004,AD39) -> 10 | AK39: =AF39+AH39 -> -260000
B40: I-1011 | C40: 46223.649 | E40: INGRESOS | H40: CUOTA | K40: Pago de cuota [C-0133] de Magdalena Itati Ramos por actividad de Complemento | P40: 37.044.300 | S40: FITNESS | U40: 30000 | X40: 0 | Z40: COMPLETADO | AB40: Transferencia | AD40: SALARIOS | AF40: =SUMIFS($U$13:$U$2004,$H$13:$H$2004,AD40,$E$13:$E$2004,$AF$29) -> 0 | AH40: =SUMIFS($U$13:$U$2004,$H$13:$H$2004,AD40,$E$13:$E$2004,$AH$29,$Z13:$Z2004,"COMPLETADO")*-1 -> -60000 | AJ40: =COUNTIF($H$13:$H$2004,AD40) -> 1 | AK40: =AF40+AH40 -> -60000
B41: E-1010 | C41: 46223.526 | E41: EGRESOS | H41: PUBLICIDAD | K41: Video para promoción de colecta | P41: 00.000.000 | S41: OTROS | U41: 20000 | X41: 0 | Z41: COMPLETADO | AB41: Transferencia | AD41: MANTENIM. | AF41: =SUMIFS($U$13:$U$2004,$H$13:$H$2004,AD41,$E$13:$E$2004,$AF$29) -> 125000 | AH41: =SUMIFS($U$13:$U$2004,$H$13:$H$2004,AD41,$E$13:$E$2004,$AH$29,$Z13:$Z2004,"COMPLETADO")*-1 -> -355450 | AJ41: =COUNTIF($H$13:$H$2004,AD41) -> 13 | AK41: =AF41+AH41 -> -230450
B42: I-1009 | C42: 46222.841 | E42: INGRESOS | H42: KIOSCO | K42: SALDO A LIQUIDAR - Cantina Kiosco - 13/7/2026 al 19/7/2026 | P42: 29.596.385 | S42: CANTINA | U42: 5150 | X42: 0 | Z42: COMPLETADO | AB42: Transferencia | AD42: LUZ | AF42: =SUMIFS($U$13:$U$2004,$H$13:$H$2004,AD42,$E$13:$E$2004,$AF$29) -> 0 | AH42: =SUMIFS($U$13:$U$2004,$H$13:$H$2004,AD42,$E$13:$E$2004,$AH$29,$Z13:$Z2004,"COMPLETADO")*-1 -> -686455 | AJ42: =COUNTIF($H$13:$H$2004,AD42) -> 2 | AK42: =AF42+AH42 -> -686455
...

Sheet LOCAL 1
B2: LOCAL 1 | F2: ↓ Actividad ↓ | M2: Inicio de Actividad: | P2: 46089 | T2: SALDO TOTAL | X2: SALDO A LIQUIDAR | AB2: LIQUID. 30 DÍAS | AF2: INGRESO TOTAL | AJ2: EGRESO TOTAL | AN2: BALANCE
F3: Estudio de Tattoo | M3: Estado: | T3: 0 | X3: =((SUMIFS($P$10:$P$801,$E$10:$E$801,"INGRESOS",$G$10:$G$801,"TATTOO",$V$10:$V$801,"*ADO")+SUMIFS($P$10:$P$801,$E$10:$E$801,"INGRESOS",$G$10:$G$801,"VENTAS",$V$10:$V$801,"*ADO")+SUMIFS($P$10:$P$801,$E$10:$E$801,"INGRESOS",$G$10:$G$801,"PIERCING",$V$10:$V$801,"*ADO"))/2)-SUMIFS($P$10:$P$801,$E$10:$E$801,"EGRESOS",$G$10:$G$801,"COMISIÓN",$V$10:$V$801,"PAGADO") -> 0 | AB3: =SUMIFS($P$10:$P$801,$E$10:$E$801,"EGRESOS",$G$10:$G$801,"COMISIÓN",$Y$10:$Y$801,"COMPLETADO",$C$10:$C$801,">="&DASHBOARD!$AY$2-30,$C$10:$C$801,"<="&DASHBOARD!$AY$2) -> 991900 | AF3: =SUMIFS($P$10:$P$801,$E$10:$E$801,"INGRESOS",$G$10:$G801,"VENTAS",$V$10:$V$801,"*ADO")+(SUMIFS($P$10:$P$801,$E$10:$E$801,"INGRESOS",$G$10:$G801,"COMISIÓN",$V$10:$V$801,"*ADO")) -> 6374800 | AJ3: =SUMIFS($P$10:$P$801,$E$10:$E$801,"EGRESOS",$G$10:$G$801,"COMISIÓN",$V$10:$V$801,"*ADO")+SUMIFS($P$10:$P$801,$E$10:$E$801,"EGRESOS",$G$10:$G$801,"CMV",$V$10:$V$801,"*ADO") -> 3087400 | AN3: =AF3-AJ3-X3 -> 3287400
B6: Salud: | F6: Estado Municipal: | I6: En proceso | M6: Estado Financiero: | P6: =IF(T3<0,"Adeudando",IF(X3>0,"Saldo a liquidar",IF(AB3=0,"Sin movimientos",IF(X3=0,"Saldado",)))) -> Saldado | T6: LIQUIDAR TOTAL | X6: LIQUIDAR: → | AB6: 0
B8: MOVIMIENTOS
B9: Id. | C9: Fecha | E9: Tipo | G9: Categoría | I9: Concepto | N9: Contra-parte | P9: Monto | R9: Impuestos | T9: M.P. | V9: Estado Finan. | Y9: Estado | AB9: INGRESOS | AJ9: GASTOS
B10: I-1036 | C10: 46226.844 | E10: INGRESOS | G10: VENTAS | I10: Seña Tattoo - Minitattoo Silvina | N10: 35.872.158 | P10: 20000 | R10: 0 | T10: Transferencia | V10: SEÑADO | Y10: COMPLETADO | AB10: Enero | AD10: =SUMIFS($P$10:$P$811,$C$10:$C$811,">="&DATE(2026,1,1),$C$10:$C$811,"<"&DATE(2026,2,1),$E$10:$E$811,"INGRESOS",$Y$10:$Y$811,"COMPLETADO") -> 0 | AF10: Febrero | AH10: =SUMIFS($P$10:$P$811,$C$10:$C$811,">="&DATE(2026,2,1),$C$10:$C$811,"<"&DATE(2026,3,1),$E$10:$E$811,"INGRESOS",$Y$10:$Y$811,"COMPLETADO") -> 0 | AJ10: Enero | AL10: =-SUMIFS($P$10:$P$811,$C$10:$C$811,">="&DATE(2026,1,1),$C$10:$C$811,"<"&DATE(2026,2,1),$E$10:$E$811,"EGRESOS",$Y$10:$Y$811,"COMPLETADO") -> 0 | AN10: Febrero | AP10: =-SUMIFS($P$10:$P$811,$C$10:$C$811,">="&DATE(2026,2,1),$C$10:$C$811,"<"&DATE(2026,3,1),$E$10:$E$811,"EGRESOS",$Y$10:$Y$811,"COMPLETADO") -> 0
B11: I-1035 | C11: 46226.842 | E11: INGRESOS | G11: VENTAS | I11: Seña Tattoo - Mundialista Pamela | N11: 35.872.158 | P11: 40000 | R11: 0 | T11: Transferencia | V11: SEÑADO | Y11: COMPLETADO | AB11: Marzo | AD11: =SUMIFS($P$10:$P$811,$C$10:$C$811,">="&DATE(2026,3,1),$C$10:$C$811,"<"&DATE(2026,4,1),$E$10:$E$811,"INGRESOS",$Y$10:$Y$811,"COMPLETADO") -> 769000 | AF11: Abril | AH11: =SUMIFS($P$10:$P$811,$C$10:$C$811,">="&DATE(2026,4,1),$C$10:$C$811,"<"&DATE(2026,5,1),$E$10:$E$811,"INGRESOS",$Y$10:$Y$811,"COMPLETADO") -> 1652500 | AJ11: Marzo | AL11: =-SUMIFS($P$10:$P$811,$C$10:$C$811,">="&DATE(2026,3,1),$C$10:$C$811,"<"&DATE(2026,4,1),$E$10:$E$811,"EGRESOS",$Y$10:$Y$811,"COMPLETADO") -> -852065 | AN11: Abril | AP11: =-SUMIFS($P$10:$P$811,$C$10:$C$811,">="&DATE(2026,4,1),$C$10:$C$811,"<"&DATE(2026,5,1),$E$10:$E$811,"EGRESOS",$Y$10:$Y$811,"COMPLETADO") -> -792400
B12: E-1032 | C12: 46226.591 | E12: EGRESOS | G12: COMISIÓN | I12: Pago de SALDO A LIQUIDAR - 23/7/2026 | N12: 35.872.158 | P12: 45000 | R12: 0 | T12: Transferencia | V12: PAGADO | Y12: COMPLETADO | AB12: Mayo | AD12: =SUMIFS($P$10:$P$811,$C$10:$C$811,">="&DATE(2026,5,1),$C$10:$C$811,"<"&DATE(2026,6,1),$E$10:$E$811,"INGRESOS",$Y$10:$Y$811,"COMPLETADO") -> 614500 | AF12: Junio | AH12: =SUMIFS($P$10:$P$811,$C$10:$C$811,">="&DATE(2026,6,1),$C$10:$C$811,"<"&DATE(2026,7,1),$E$10:$E$811,"INGRESOS",$Y$10:$Y$811,"COMPLETADO") -> 1962500 | AJ12: Mayo | AL12: =-SUMIFS($P$10:$P$811,$C$10:$C$811,">="&DATE(2026,5,1),$C$10:$C$811,"<"&DATE(2026,6,1),$E$10:$E$811,"EGRESOS",$Y$10:$Y$811,"COMPLETADO") -> -293500 | AN12: Junio | AP12: =-SUMIFS($P$10:$P$811,$C$10:$C$811,">="&DATE(2026,6,1),$C$10:$C$811,"<"&DATE(2026,7,1),$E$10:$E$811,"EGRESOS",$Y$10:$Y$811,"COMPLETADO") -> -865000
B13: I-1031 | C13: 46226.59 | E13: INGRESOS | G13: VENTAS | I13: Seña Tattoo - minitattoos en la mano Virginia | N13: 35.872.158 | P13: 30000 | R13: 0 | T13: Transferencia | V13: SEÑADO | Y13: COMPLETADO | AB13: Julio | AD13: =SUMIFS($P$10:$P$811,$C$10:$C$811,">="&DATE(2026,7,1),$C$10:$C$811,"<"&DATE(2026,8,1),$E$10:$E$811,"INGRESOS",$Y$10:$Y$811,"COMPLETADO") -> 1736300 | AF13: Agosto | AH13: =SUMIFS($P$10:$P$811,$C$10:$C$811,">="&DATE(2026,8,1),$C$10:$C$811,"<"&DATE(2026,9,1),$E$10:$E$811,"INGRESOS",$Y$10:$Y$811,"COMPLETADO") -> 0 | AJ13: Julio | AL13: =-SUMIFS($P$10:$P$811,$C$10:$C$811,">="&DATE(2026,7,1),$C$10:$C$811,"<"&DATE(2026,8,1),$E$10:$E$811,"EGRESOS",$Y$10:$Y$811,"COMPLETADO") -> -854400 | AN13: Agosto | AP13: =-SUMIFS($P$10:$P$811,$C$10:$C$811,">="&DATE(2026,8,1),$C$10:$C$811,"<"&DATE(2026,9,1),$E$10:$E$811,"EGRESOS",$Y$10:$Y$811,"COMPLETADO") -> 0
B14: E-1024 | C14: 46225.704 | E14: EGRESOS | G14: COMISIÓN | I14: Pago de SALDO A LIQUIDAR - 22/7/2026 | N14: 35.872.158 | P14: 150000 | R14: 0 | T14: Efectivo | V14: PAGADO | Y14: COMPLETADO | AB14: Septiembre | AD14: =SUMIFS($P$10:$P$811,$C$10:$C$811,">="&DATE(2026,9,1),$C$10:$C$811,"<"&DATE(2026,10,1),$E$10:$E$811,"INGRESOS",$Y$10:$Y$811,"COMPLETADO") -> 0 | AF14: Octubre | AH14: =SUMIFS($P$10:$P$811,$C$10:$C$811,">="&DATE(2026,10,1),$C$10:$C$811,"<"&DATE(2026,11,1),$E$10:$E$811,"INGRESOS",$Y$10:$Y$811,"COMPLETADO") -> 0 | AJ14: Septiembre | AL14: =-SUMIFS($P$10:$P$811,$C$10:$C$811,">="&DATE(2026,9,1),$C$10:$C$811,"<"&DATE(2026,10,1),$E$10:$E$811,"EGRESOS",$Y$10:$Y$811,"COMPLETADO") -> 0 | AN14: Octubre | AP14: =-SUMIFS($P$10:$P$811,$C$10:$C$811,">="&DATE(2026,10,1),$C$10:$C$811,"<"&DATE(2026,11,1),$E$10:$E$811,"EGRESOS",$Y$10:$Y$811,"COMPLETADO") -> 0
B15: I-1023 | C15: 46225.702 | E15: INGRESOS | G15: VENTAS | I15: Tattoo - Manga floral Isabel | N15: 35.872.158 | P15: 300000 | R15: 0 | T15: Efectivo | V15: PAGADO | Y15: COMPLETADO | AB15: Noviembre | AD15: =SUMIFS($P$10:$P$811,$C$10:$C$811,">="&DATE(2026,11,1),$C$10:$C$811,"<"&DATE(2026,12,1),$E$10:$E$811,"INGRESOS",$Y$10:$Y$811,"COMPLETADO") -> 0 | AF15: Diciembre | AH15: =SUMIFS($P$10:$P$811,$C$10:$C$811,">="&DATE(2026,12,1),$C$10:$C$811,"<"&DATE(2027,1,1),$E$10:$E$811,"INGRESOS",$Y$10:$Y$811,"COMPLETADO") -> 0 | AJ15: Noviembre | AL15: =-SUMIFS($P$10:$P$811,$C$10:$C$811,">="&DATE(2026,11,1),$C$10:$C$811,"<"&DATE(2026,12,1),$E$10:$E$811,"EGRESOS",$Y$10:$Y$811,"COMPLETADO") -> 0 | AN15: Diciembre | AP15: =-SUMIFS($P$10:$P$811,$C$10:$C$811,">="&DATE(2026,12,1),$C$10:$C$811,"<"&DATE(2027,1,1),$E$10:$E$811,"EGRESOS",$Y$10:$Y$811,"COMPLETADO") -> 0
B16: E-1022 | C16: 46225.699 | E16: EGRESOS | G16: COMISIÓN | I16: Pago de SALDO A LIQUIDAR - 22/7/2026 | N16: 35.872.158 | P16: 25000 | R16: 0 | T16: Transferencia | V16: PAGADO | Y16: COMPLETADO | AB16: TOTAL | AF16: =SUM(AD10:AE15,AH10:AI15) -> 6734800 | AJ16: TOTAL | AN16: =SUM(AL10:AM15,AP10:AQ15) -> -3657365
B17: I-1021 | C17: 46225.697 | E17: INGRESOS | G17: VENTAS | I17: Seña Tattoo - Proyecto cobertura cicatrices Paula | N17: 35.872.158 | P17: 50000 | R17: 0 | T17: Transferencia | V17: SEÑADO | Y17: COMPLETADO
B18: E-1004 | C18: 46222.455 | E18: EGRESOS | G18: COMISIÓN | I18: Pago de SALDO A LIQUIDAR - 19/7/2026 | N18: 35.872.158 | P18: 25000 | R18: 0 | T18: Efectivo | V18: PAGADO | Y18: COMPLETADO | AB18: UTILIDAD | AK18: CRECIM. ECONÓM. | AO18: CRECIM. CLIENTES
B19: I-1003 | C19: 46222.452 | E19: INGRESOS | G19: VENTAS | I19: Tattoo - Manga floral Isabel | N19: 35.872.158 | P19: 50000 | R19: 0 | T19: Efectivo | V19: PAGADO | Y19: COMPLETADO | AB19: Enero | AD19: =AD10+AL10 -> 0 | AF19: Febrero | AH19: =AH10+AP10 -> 0 | AO19: No aplica
B20: E-1002 | C20: 46221.006 | E20: EGRESOS | G20: COMISIÓN | I20: Pago de SALDO A LIQUIDAR - 18/7/2026 | N20: 35.872.158 | P20: 25000 | R20: 0 | T20: Transferencia | V20: PAGADO | Y20: COMPLETADO | AB20: Marzo | AD20: =AD11+AL11 -> -83065 | AF20: Abril | AH20: =AH11+AP11 -> 860100
B21: E-1000 | C21: 46221.004 | E21: EGRESOS | G21: COMISIÓN | I21: Pago de SALDO A LIQUIDAR - 18/7/2026 | N21: 35.872.158 | P21: 75000 | R21: 0 | T21: Efectivo | V21: PAGADO | Y21: COMPLETADO | AB21: Mayo | AD21: =AD12+AL12 -> 321000 | AF21: Junio | AH21: =AH12+AP12 -> 1097500
B22: I-0998 | C22: 46221.003 | E22: INGRESOS | G22: VENTAS | I22: Seña Tattoo - Lineas finas manga Micaela | N22: 35.872.158 | P22: 50000 | R22: 0 | T22: Transferencia | V22: SEÑADO | Y22: COMPLETADO | AB22: Julio | AD22: =AD13+AL13 -> 881900 | AF22: Agosto | AH22: =AH13+AP13 -> 0 | AM22: CRECIMIENTO %
B23: I-0996 | C23: 46221.001 | E23: INGRESOS | G23: VENTAS | I23: Tattoo - Manga floral Isabel | N23: 35.872.158 | P23: 150000 | R23: 0 | T23: Efectivo | V23: PAGADO | Y23: COMPLETADO | AB23: Septiembre | AD23: =AD14+AL14 -> 0 | AF23: Octubre | AH23: =AH14+AP14 -> 0
B24: E-0981 | C24: 46218.825 | E24: EGRESOS | G24: COMISIÓN | I24: Pago de SALDO A LIQUIDAR - 15/7/2026 | N24: 35.872.158 | P24: 35000 | R24: 0 | T24: Transferencia | V24: PAGADO | Y24: COMPLETADO | AB24: Noviembre | AD24: =AD15+AL15 -> 0 | AF24: Diciembre | AH24: =AH15+AP15 -> 0
B25: E-0980 | C25: 46218.823 | E25: EGRESOS | G25: COMISIÓN | I25: Pago de SALDO A LIQUIDAR - 15/7/2026 | N25: 35.872.158 | P25: 70000 | R25: 0 | T25: Efectivo | V25: PAGADO | Y25: COMPLETADO | AB25: TOTAL | AF25: =SUM(AD19:AE24,AH19:AI24) -> 3077435
B26: I-0979 | C26: 46218.822 | E26: INGRESOS | G26: VENTAS | I26: Tattoo - Proyecto Candela Dragones y 2 minitattoos | N26: 35.872.158 | P26: 70000 | R26: 0 | T26: Transferencia | V26: PAGADO | Y26: COMPLETADO
B27: I-0978 | C27: 46218.82 | E27: INGRESOS | G27: VENTAS | I27: Tattoo - Proyecto Candela Dragones y 2 minitattoos | N27: 35.872.158 | P27: 140000 | R27: 0 | T27: Efectivo | V27: PAGADO | Y27: COMPLETADO
B28: I-0971 | C28: 46217.681 | E28: INGRESOS | G28: VENTAS | I28: Pago (PARCIAL) Tattoo - Minitattoo Silvina | N28: 35.872.158 | P28: 20000 | R28: 0 | T28: Transferencia | V28: PAGADO | Y28: COMPLETADO
B29: E-0969 | C29: 46217.662 | E29: EGRESOS | G29: COMISIÓN | I29: Pago de SALDO A LIQUIDAR - 14/7/2026 | N29: 35.872.158 | P29: 55000 | R29: 0 | T29: Transferencia | V29: PAGADO | Y29: COMPLETADO
B30: I-0967 | C30: 46217.658 | E30: INGRESOS | G30: VENTAS | I30: Pago (PARCIAL) Tattoo - Proyecto Fabian | N30: 35.872.158 | P30: 30000 | R30: 0 | T30: Transferencia | V30: PAGADO | Y30: COMPLETADO
B31: I-0966 | C31: 46217.653 | E31: INGRESOS | G31: VENTAS | I31: Seña Tattoo - Candela pierna y 2 minitattos | N31: 35.872.158 | P31: 60000 | R31: 0 | T31: Transferencia | V31: SEÑADO | Y31: COMPLETADO
B32: E-0942 | C32: 46213.865 | E32: EGRESOS | G32: COMISIÓN | I32: Pago de SALDO A LIQUIDAR - 10/7/2026 | N32: 35.872.158 | P32: 40000 | R32: 0 | T32: Efectivo | V32: PAGADO | Y32: COMPLETADO
B33: I-0941 | C33: 46213.864 | E33: INGRESOS | G33: VENTAS | I33: Tattoo - 4 minitattoos nalga | N33: 35.872.158 | P33: 80000 | R33: 0 | T33: Efectivo | V33: PAGADO | Y33: COMPLETADO
B34: E-0930 | C34: 46212.687 | E34: EGRESOS | G34: COMISIÓN | I34: Pago de SALDO A LIQUIDAR - 9/7/2026 | N34: 35.872.158 | P34: 74400 | R34: 0 | T34: Transferencia | V34: PAGADO | Y34: COMPLETADO
B35: I-0929 | C35: 46212.686 | E35: INGRESOS | G35: VENTAS | I35: Tattoo - Nahiara brazo | N35: 35.872.158 | P35: 148800 | R35: 0 | T35: Transferencia | V35: PAGADO | Y35: COMPLETADO
B36: E-0924 | C36: 46211.96 | E36: EGRESOS | G36: COMISIÓN | I36: Pago de SALDO A LIQUIDAR - 8/7/2026 | N36: 35.872.158 | P36: 60000 | R36: 0 | T36: Transferencia | V36: PAGADO | Y36: COMPLETADO
B37: E-0923 | C37: 46211.958 | E37: EGRESOS | G37: COMISIÓN | I37: Pago de SALDO A LIQUIDAR - 8/7/2026 | N37: 35.872.158 | P37: 20000 | R37: 0 | T37: Efectivo | V37: PAGADO | Y37: COMPLETADO
... B172: E-0011 | C172: 46084.852 | E172: EGRESOS | G172: REPARACIONES | I172: Cambio de cerradura | N172: 00.000.000 | P172: 50000 | R172: 0 | T172: Efectivo | V172: PAGADO | Y172: COMPLETADO

Sheet FITNESS
B2: FITNESS | F2: ↓ Actividad ↓ | M2: Inicio de Actividad: | P2: 46111 | T2: SALDO TOTAL | X2: SALDO A LIQUIDAR | AB2: LIQUID. 30 DÍAS | AF2: INGRESO TOTAL | AJ2: EGRESO TOTAL | AN2: BALANCE | AR2: Funcional | AT2: =COUNTIFS($AV$20:$AV$815,"<>Abandonado",$AP$20:$AP$815,AR2) -> 51 | AU2: 26000 | AV2: PPP ($) | AX2: =SUMPRODUCT(AT2:AT6,AU2:AU6)/SUM(AT2:AT6) -> 26480.392
F3: Zona Fitness | M3: Estado: | T3: =(SUMIFS($P$20:$P$800,$G$20:$G$800,"CUOTA",$V$20:$V$800,"PAGADO"))/2 -> 3758500 | X3: =((SUMIFS($P$20:$P$811,$E$20:$E$811,"INGRESOS",$G$20:$G$811,"CUOTA",$V$20:$V$811,"*ADO")+SUMIFS($P$20:$P$811,$E$20:$E$811,"INGRESOS",$G$20:$G$811,"INSCRIPCIÓN",$V$20:$V$811,"*ADO")+SUMIFS($P$20:$P$811,$E$20:$E$811,"INGRESOS",$G$20:$G$811,"CLASES",$V$20:$V$811,"*ADO"))/2)-SUMIFS($P$20:$P$811,$E$20:$E$811,"EGRESOS",$G$20:$G$811,"COMISIÓN",$V$20:$V$811,"PAGADO") -> 923500 | AB3: =SUMIFS($P$20:$P$811,$E$20:$E$811,"EGRESOS",$G$20:$G$811,"COMISIÓN",$Y$20:$Y$811,"COMPLETADO",$C$20:$C$811,">="&DASHBOARD!$AY$2-30,$C$20:$C$811,"<="&DASHBOARD!$AY$2) -> 1085000 | AF3: =SUMIFS($P$20:$P$801,$E$20:$E$801,"INGRESOS",$G$20:$G801,"CUOTA",$V$20:$V$801,"*ADO")+(SUMIFS($P$20:$P$801,$E$20:$E$801,"INGRESOS",$G$20:$G801,"COMISIÓN",$V$20:$V$801,"*ADO")) -> 7517000 | AJ3: =SUMIFS($P$20:$P$801,$E$20:$E$801,"EGRESOS",$G$20:$G$801,"COMISIÓN",$V$20:$V$801,"*ADO")+SUMIFS($P$20:$P$801,$E$20:$E$801,"EGRESOS",$G$20:$G$801,"CMV",$V$20:$V$801,"*ADO") -> 2835000 | AN3: =AF3-AJ3-X3 -> 3758500 | AW3: 25000
AR4: Complemento | AT4: =COUNTIFS($AV$20:$AV$815,"<>Abandonado",$AP$20:$AP$815,AR4) -> 46 | AU4: 25000 | AV4: PP (Real) ($) | AX4: =SUMIFS(AT20:AT815,AT20:AT815,">0",AV20:AV815,"<>Abandonado")/COUNTIFS(AT20:AT815,">0",AV20:AV815,"<>Abandonado") -> 31287.129
B6: Salud: | F6: Estado Municipal: | I6: Iniciando | M6: Estado Financiero: | P6: =IF(T3<0,"Adeudando",IF(X3>0,"Saldo a liquidar",IF(AB3=0,"Sin movimientos",IF(X3=0,"Saldado",)))) -> Saldo a liquidar | T6: LIQUIDAR TOTAL | X6: LIQUIDAR: → | AB6: 0 | AF6: Insc. Activos | AH6: =COUNTIF($AV$20:$AV$815,"<>Abandonado")-COUNTIF($AV$20:$AV$815,"") -> 102 | AR6: Combo F+C | AT6: =COUNTIFS($AV$20:$AV$815,"<>Abandonado",$AP$20:$AP$815,AR6) -> 5 | AU6: 45000 | AV6: Adeudado | AX6: =SUMIF(AV20:AV820,"Adeudando",AT20:AT820) -> 1080000
B8: CARGAR INSCRIPCIÓN | T8: CARGAR PAGO DE CUOTA | AB8: INGRESOS | AJ8: GASTOS | AR8: UTILIDAD
B9: Nombre | E9: Apellido | H9: D.N.I. | J9: Tel. | M9: Actividad | P9: Modalidad | T9: D.N.I. | W9: Nombre | AB9: Enero | AD9: =SUMIFS($P$20:$P$811,$C$20:$C$811,">="&DATE(2026,1,1),$C$20:$C$811,"<"&DATE(2026,2,1),$E$20:$E$811,"INGRESOS",$Y$20:$Y$811,"COMPLETADO") -> 0 | AF9: Febrero | AH9: =SUMIFS($P$20:$P$811,$C$20:$C$811,">="&DATE(2026,2,1),$C$20:$C$811,"<"&DATE(2026,3,1),$E$20:$E$811,"INGRESOS",$Y$20:$Y$811,"COMPLETADO") -> 0 | AJ9: Enero | AL9: =-SUMIFS($P$20:$P$811,$C$20:$C$811,">="&DATE(2026,1,1),$C$20:$C$811,"<"&DATE(2026,2,1),$E$20:$E$811,"EGRESOS",$Y$20:$Y$811,"COMPLETADO") -> 0 | AN9: Febrero | AP9: =-SUMIFS($P$20:$P$811,$C$20:$C$811,">="&DATE(2026,2,1),$C$20:$C$811,"<"&DATE(2026,3,1),$E$20:$E$811,"EGRESOS",$Y$20:$Y$811,"COMPLETADO") -> 0 | AR9: Enero | AT9: =AD9+AL9 -> 0 | AV9: Febrero | AX9: =AH9+AP9 -> 0
AB10: Marzo | AD10: =SUMIFS($P$20:$P$811,$C$20:$C$811,">="&DATE(2026,3,1),$C$20:$C$811,"<"&DATE(2026,4,1),$E$20:$E$811,"INGRESOS",$Y$20:$Y$811,"COMPLETADO") -> 89500 | AF10: Abril | AH10: =SUMIFS($P$20:$P$811,$C$20:$C$811,">="&DATE(2026,4,1),$C$20:$C$811,"<"&DATE(2026,5,1),$E$20:$E$811,"INGRESOS",$Y$20:$Y$811,"COMPLETADO") -> 1622500 | AJ10: Marzo | AL10: =-SUMIFS($P$20:$P$811,$C$20:$C$811,">="&DATE(2026,3,1),$C$20:$C$811,"<"&DATE(2026,4,1),$E$20:$E$811,"EGRESOS",$Y$20:$Y$811,"COMPLETADO") -> -1298067 | AN10: Abril | AP10: =-SUMIFS($P$20:$P$811,$C$20:$C$811,">="&DATE(2026,4,1),$C$20:$C$811,"<"&DATE(2026,5,1),$E$20:$E$811,"EGRESOS",$Y$20:$Y$811,"COMPLETADO") -> -14300 | AR10: Marzo | AT10: =AD10+AL10 -> -1208567 | AV10: Abril | AX10: =AH10+AP10 -> 1608200
B11: Monto de cuota | E11: Descuento (%) | H11: Promoción (-$) | K11: Entrenador | P11: Turno Pref. | T11: Apellido | W11: Monto a pagar | AB11: Mayo | AD11: =SUMIFS($P$20:$P$811,$C$20:$C$811,">="&DATE(2026,5,1),$C$20:$C$811,"<"&DATE(2026,6,1),$E$20:$E$811,"INGRESOS",$Y$20:$Y$811,"COMPLETADO") -> 2141500 | AF11: Junio | AH11: =SUMIFS($P$20:$P$811,$C$20:$C$811,">="&DATE(2026,6,1),$C$20:$C$811,"<"&DATE(2026,7,1),$E$20:$E$811,"INGRESOS",$Y$20:$Y$811,"COMPLETADO") -> 2297500 | AJ11: Mayo | AL11: =-SUMIFS($P$20:$P$811,$C$20:$C$811,">="&DATE(2026,5,1),$C$20:$C$811,"<"&DATE(2026,6,1),$E$20:$E$811,"EGRESOS",$Y$20:$Y$811,"COMPLETADO") -> -837500 | AN11: Junio | AP11: =-SUMIFS($P$20:$P$811,$C$20:$C$811,">="&DATE(2026,6,1),$C$20:$C$811,"<"&DATE(2026,7,1),$E$20:$E$811,"EGRESOS",$Y$20:$Y$811,"COMPLETADO") -> -912500 | AR11: Mayo | AT11: =AD11+AL11 -> 1304000 | AV11: Junio | AX11: =AH11+AP11 -> 1385000
B12: =IF(AND(M10="Funcional",P10="Reducida"),30000,IF(AND(M10="Funcional",P10="Completa"),35000,IF(M10="Complemento",30000,IF(M10="Combo F+C",50000,0))))-H12 -> 0 | AB12: Julio | AD12: =SUMIFS($P$20:$P$811,$C$20:$C$811,">="&DATE(2026,7,1),$C$20:$C$811,"<"&DATE(2026,8,1),$E$20:$E$811,"INGRESOS",$Y$20:$Y$811,"COMPLETADO") -> 1874500 | AF12: Agosto | AH12: =SUMIFS($P$20:$P$811,$C$20:$C$811,">="&DATE(2026,8,1),$C$20:$C$811,"<"&DATE(2026,9,1),$E$20:$E$811,"INGRESOS",$Y$20:$Y$811,"COMPLETADO") -> 0 | AJ12: Julio | AL12: =-SUMIFS($P$20:$P$811,$C$20:$C$811,">="&DATE(2026,7,1),$C$20:$C$811,"<"&DATE(2026,8,1),$E$20:$E$811,"EGRESOS",$Y$20:$Y$811,"COMPLETADO") -> -1085000 | AN12: Agosto | AP12: =-SUMIFS($P$20:$P$811,$C$20:$C$811,">="&DATE(2026,8,1),$C$20:$C$811,"<"&DATE(2026,9,1),$E$20:$E$811,"EGRESOS",$Y$20:$Y$811,"COMPLETADO") -> 0 | AR12: Julio | AT12: =AD12+AL12 -> 789500 | AV12: Agosto | AX12: =AH12+AP12 -> 0
B13: * Condición médica o especificación del estado de salud | T13: Estado | W13: M.P. | AB13: Septiembre | AD13: =SUMIFS($P$20:$P$811,$C$20:$C$811,">="&DATE(2026,9,1),$C$20:$C$811,"<"&DATE(2026,10,1),$E$20:$E$811,"INGRESOS",$Y$20:$Y$811,"COMPLETADO") -> 0 | AF13: Octubre | AH13: =SUMIFS($P$20:$P$811,$C$20:$C$811,">="&DATE(2026,10,1),$C$20:$C$811,"<"&DATE(2026,11,1),$E$20:$E$811,"INGRESOS",$Y$20:$Y$811,"COMPLETADO") -> 0 | AJ13: Septiembre | AL13: =-SUMIFS($P$20:$P$811,$C$20:$C$811,">="&DATE(2026,9,1),$C$20:$C$811,"<"&DATE(2026,10,1),$E$20:$E$811,"EGRESOS",$Y$20:$Y$811,"COMPLETADO") -> 0 | AN13: Octubre | AP13: =-SUMIFS($P$20:$P$811,$C$20:$C$811,">="&DATE(2026,10,1),$C$20:$C$811,"<"&DATE(2026,11,1),$E$20:$E$811,"EGRESOS",$Y$20:$Y$811,"COMPLETADO") -> 0 | AR13: Septiembre | AT13: =AD13+AL13 -> 0 | AV13: Octubre | AX13: =AH13+AP13 -> 0
AB14: Noviembre | AD14: =SUMIFS($P$20:$P$811,$C$20:$C$811,">="&DATE(2026,11,1),$C$20:$C$811,"<"&DATE(2026,12,1),$E$20:$E$811,"INGRESOS",$Y$20:$Y$811,"COMPLETADO") -> 0 | AF14: Diciembre | AH14: =SUMIFS($P$20:$P$811,$C$20:$C$811,">="&DATE(2026,12,1),$C$20:$C$811,"<"&DATE(2027,1,1),$E$20:$E$811,"INGRESOS",$Y$20:$Y$811,"COMPLETADO") -> 0 | AJ14: Noviembre | AL14: =-SUMIFS($P$10:$P$811,$C$10:$C$811,">="&DATE(2026,11,1),$C$10:$C$811,"<"&DATE(2026,12,1),$E$10:$E$811,"EGRESOS",$Y$10:$Y$811,"COMPLETADO") -> 0 | AN14: Diciembre | AP14: =-SUMIFS($P$10:$P$811,$C$10:$C$811,">="&DATE(2026,12,1),$C$10:$C$811,"<"&DATE(2027,1,1),$E$10:$E$811,"EGRESOS",$Y$10:$Y$811,"COMPLETADO") -> 0 | AR14: Noviembre | AT14: =AD14+AL14 -> 0 | AV14: Diciembre | AX14: =AH14+AP14 -> 0
AB15: TOTAL | AF15: =SUM(AD9:AE14,AH9:AI14) -> 8025500 | AJ15: TOTAL | AN15: =SUM(AL9:AM14,AP9:AQ14) -> -4147367 | AR15: TOTAL | AV15: =SUM(AT9:AU14,AX9:AY14) -> 3878133
B18: MOVIMIENTOS | AB18: INSCRIPTOS
B19: Id. | C19: Fecha | E19: Tipo | G19: Categoría | I19: Concepto | N19: Contra-parte | P19: Monto | R19: Impuestos | T19: M.P. | V19: Estado Finan. | Y19: Estado | AB19: Id. | AD19: Fecha | AF19: Nombre | AI19: Apellido | AL19: D.N.I. | AN19: Tel. | AP19: Actividad | AR19: Modalidad | AT19: Cuota | AV19: Estado | AY19: Instructor | BA19: Vence
B20: I-1038 | C20: 46227.655 | E20: INGRESOS | G20: CUOTA | I20: Pago de cuota [F-0027] de Patricia Feldick por actividad de Funcional | N20: 20.118.913 | P20: 0 | R20: 0 | T20: Efectivo | V20: PAGADO | Y20: COMPLETADO | AB20: C-0141 | AD20: 46226.841 | AF20: Rocio Itati | AI20: Araujo | AL20: 42.763.346 | AN20: 3743501958 | AP20: Complemento | AR20: Completa | AT20: 30000 | AV20: Nuevo inscripto | BA20: SIN PAGOS
B21: I-1028 | C21: 46225.829 | E21: INGRESOS | G21: CUOTA | I21: Pago de cuota [F-0018] de Silvina Molina por actividad de Funcional | N21: 33.720.939 | P21: 30000 | R21: 0 | T21: Transferencia | V21: PAGADO | Y21: COMPLETADO | AB21: C-0140 | AD21: 46226.84 | AF21: Mauro Nahuel | AI21: Peña | AL21: 37.460.568 | AN21: 3743555060 | AP21: Complemento | AR21: Completa | AT21: 30000 | AV21: Nuevo inscripto | BA21: SIN PAGOS
B22: I-1026 | C22: 46225.71 | E22: INGRESOS | G22: CUOTA | I22: Pago de cuota [C-0139] de Cristian Gimenez por actividad de Complemento | N22: 33.486.350 | P22: 30000 | R22: 0 | T22: Transferencia | V22: PAGADO | Y22: COMPLETADO | AB22: C-0139 | AD22: 46225.709 | AF22: Cristian | AI22: Gimenez | AL22: 33.486.350 | AN22: 3765103736 | AP22: Complemento | AR22: Completa | AT22: 30000 | AV22: Nuevo inscripto | BA22: 46256
B23: I-1025 | C23: 46225.708 | E23: INGRESOS | G23: CUOTA | I23: Pago de cuota [C-0138] de Daniela Soto por actividad de Complemento | N23: 32.608.369 | P23: 30000 | R23: 0 | T23: Transferencia | V23: PAGADO | Y23: COMPLETADO | AB23: C-0138 | AD23: 46225.707 | AF23: Daniela | AI23: Soto | AL23: 32.608.369 | AN23: 3764355176 | AP23: Complemento | AR23: Completa | AT23: 30000 | AV23: Nuevo inscripto | BA23: 46256
B24: I-1019 | C24: 46224.899 | E24: INGRESOS | G24: CUOTA | I24: Pago de cuota [F-0042] de Carolina Paredes por actividad de Funcional | N24: 28.162.967 | P24: 6000 | R24: 0 | T24: Transferencia | V24: PAGADO | Y24: COMPLETADO | AB24: C-0137 | AD24: 46223.802 | AF24: Wilson William | AI24: Zarza | AL24: 45.135.022 | AN24: 3764815672 | AP24: Complemento | AR24: Completa | AT24: 30000 | AV24: Nuevo inscripto | BA24: SIN PAGOS
B25: I-1014 | C25: 46223.732 | E25: INGRESOS | G25: CUOTA | I25: Pago de cuota [C-0136] de Walter Segovia por actividad de Complemento | N25: 20.060.193 | P25: 30000 | R25: 0 | T25: Transferencia | V25: PAGADO | Y25: COMPLETADO | AB25: C-0136 | AD25: 46223.732 | AF25: Walter | AI25: Segovia | AL25: 20.060.193 | AN25: 3764116489 | AP25: Complemento | AR25: Completa | AT25: 30000 | AV25: Nuevo inscripto | BA25: 46254
B26: I-1011 | C26: 46223.649 | E26: INGRESOS | G26: CUOTA | I26: Pago de cuota [C-0133] de Magdalena Itati Ramos por actividad de Complemento | N26: 37.044.300 | P26: 30000 | R26: 0 | T26: Transferencia | V26: PAGADO | Y26: COMPLETADO | AB26: C-0135 | AD26: 46219.655 | AF26: Victoria | AI26: Weiss | AL26: 50.731.392 | AN26: 3765372200 | AP26: Complemento | AR26: Completa | AT26: 30000 | AV26: Al día | AY26: Natanael | BA26: 46250
B27: I-0993 | C27: 46219.798 | E27: INGRESOS | G27: CUOTA | I27: Pago de cuota [C-0095] de Sergio Rolon por actividad de Complemento | N27: 48.546.483 | P27: 15000 | R27: 0 | T27: Transferencia | V27: PAGADO | Y27: COMPLETADO | AB27: C-0134 | AD27: 46219.654 | AF27: Vanesa | AI27: Campuzano | AL27: 28.818.123 | AN27: 3764851158 | AP27: Complemento | AR27: Completa | AT27: 30000 | AV27: Al día | AY27: Natanael | BA27: 46250
B28: I-0992 | C28: 46219.797 | E28: INGRESOS | G28: CUOTA | I28: Pago de cuota [C-0095] de Sergio Rolon por actividad de Complemento | N28: 48.546.483 | P28: 10000 | R28: 0 | T28: Efectivo | V28: PAGADO | Y28: COMPLETADO | AB28: C-0133 | AD28: 46219.485 | AF28: Magdalena Itati | AI28: Ramos | AL28: 37.044.300 | AN28: 3765414803 | AP28: Complemento | AR28: Completa | AT28: 30000 | AV28: Al día | AY28: Natanael | BA28: 46254
B29: I-0990 | C29: 46219.671 | E29: INGRESOS | G29: CUOTA | I29: Pago de cuota [X-0045] de Claudia Gaona por actividad de Combo F+C | N29: 22.090.381 | P29: 50000 | R29: 0 | T29: Transferencia | V29: PAGADO | Y29: COMPLETADO | AB29: F-0132 | AD29: 46217.753 | AF29: Ana María | AI29: Atamañuk | AL29: 32.085.811 | AN29: 3765043742 | AP29: Funcional | AR29: Reducida | AT29: 30000 | AV29: Al día | AY29: Natanael | BA29: 46248
B30: I-0987 | C30: 46219.659 | E30: INGRESOS | G30: CUOTA | I30: Pago de cuota [C-0135] de Victoria Weiss por actividad de Complemento | N30: 50.731.392 | P30: 25000 | R30: 0 | T30: Efectivo | V30: PAGADO | Y30: COMPLETADO | AB30: C-0131 | AD30: 46216.467 | AF30: Tadeo | AI30: Loyzate | AL30: 48.950.707 | AN30: 3765494643 | AP30: Complemento | AR30: Completa | AT30: 30000 | AV30: Al día | AY30: Natanael | BA30: 46247
B31: I-0986 | C31: 46219.657 | E31: INGRESOS | G31: CUOTA | I31: Pago de cuota [C-0134] de Vanesa Campuzano por actividad de Complemento | N31: 28.818.123 | P31: 25000 | R31: 0 | T31: Efectivo | V31: PAGADO | Y31: COMPLETADO | AB31: F-0130 | AD31: 46213.742 | AF31: Melanie | AI31: Rojas | AL31: 48.649.568 | AN31: 3764198523 | AP31: Funcional | AR31: Reducida | AT31: 30000 | AV31: Al día | AY31: Natanael | BA31: 46244
B32: I-0985 | C32: 46219.627 | E32: INGRESOS | G32: CUOTA | I32: Pago de cuota [F-0127] de Sebastian Borjas por actividad de Funcional | N32: 52.173.302 | P32: 30000 | R32: 0 | T32: Efectivo | V32: PAGADO | Y32: COMPLETADO | AB32: F-0129 | AD32: 46213.74 | AF32: Julian | AI32: Rojas | AL32: 30.531.109 | AN32: 3765093949 | AP32: Funcional | AR32: Reducida | AT32: 30000 | AV32: Al día | AY32: Natanael | BA32: 46244
B33: I-0984 | C33: 46219.624 | E33: INGRESOS | G33: CUOTA | I33: Pago de cuota [F-0123] de Margarita Ayala por actividad de Funcional | N33: 31.914.258 | P33: 35000 | R33: 0 | T33: Efectivo | V33: PAGADO | Y33: COMPLETADO | AB33: C-0128 | AD33: 46205.428 | AF33: Martiniano | AI33: Cañete Azeves | AL33: 48.798.220 | AN33: 3764858687 | AP33: Complemento | AR33: Completa | AT33: 30000 | AV33: Al día | AY33: Natanael | BA33: 46236
B34: I-0975 | C34: 46217.927 | E34: INGRESOS | G34: CUOTA | I34: Pago de cuota [F-0042] de Carolina Paredes por actividad de Funcional | N34: 28.162.967 | P34: 6000 | R34: 0 | T34: Transferencia | V34: PAGADO | Y34: COMPLETADO | AB34: F-0127 | AD34: 46202 | AF34: Sebastian | AI34: Borjas | AL34: 52.173.302 | AN34: 3764902231 | AP34: Funcional | AR34: Reducida | AT34: 30000 | AV34: Al día | AY34: Natanael | BA34: 46250
B35: I-0972 | C35: 46217.754 | E35: INGRESOS | G35: CUOTA | I35: Pago de cuota [F-0132] de Ana María Atamañuk por actividad de Funcional | N35: 32.085.811 | P35: 30000 | R35: 0 | T35: Efectivo | V35: PAGADO | Y35: COMPLETADO | AB35: C-0126 | AD35: 46196.797 | AF35: Thiara | AI35: Zevallos | AL35: 50.572.059 | AN35: 3764107207 | AP35: Complemento | AR35: Completa | AT35: 30000 | AV35: Adeudando | AY35: Natanael | BA35: 46227
B36: I-0965 | C36: 46217.482 | E36: INGRESOS | G36: CUOTA | I36: Pago de cuota [F-0050] de Rosana Neris por actividad de Funcional | N36: 25.496.779 | P36: 30000 | R36: 0 | T36: Transferencia | V36: PAGADO | Y36: COMPLETADO | AB36: F-0125 | AD36: 46196.675 | AF36: Juan Carlos | AI36: Trucheski | AL36: 36.095.636 | AN36: 3764353212 | AP36: Funcional | AR36: Completa | AT36: 35000 | AV36: Adeudando | AY36: Natanael | BA36: 46227
B37: I-0963 | C37: 46216.887 | E37: INGRESOS | G37: CUOTA | I37: Pago de cuota [C-0120] de Daniela Maciel por actividad de Complemento | N37: 50.020.164 | P37: 30000 | R37: 0 | T37: Transferencia | V37: PAGADO | Y37: COMPLETADO | AB37: C-0124 | AD37: 46196.443 | AF37: David | AI37: Raggio | AL37: 45.452.090 | AN37: 3764365497 | AP37: Complemento | AR37: Completa | AT37: 30000 | AV37: Adeudando | AY37: Natanael | BA37: 46227
... B55: I-0897 | C55: 46210.358 | E55: INGRESOS | G55: CUOTA | I55: Pago de cuota [C-0111] de Felipe Palacios por actividad de Complemento | N55: 49.694.411 | P55: 30000 | R55: 0 | T55: Transferencia | V55: PAGADO | Y55: COMPLETADO | AB55: F-0106 | AD55: 46174.789 | AF55: Leandra | AI55: Nuñes | AL55: 25.474.765 | AN55: 3764223119 | AP55: Funcional | AR55: Reducida | AT55: 30000 | AV55: Al día | AY55: Natanael | BA55: 46236
B56: I-0896 | C56: 46210.357 | E56: INGRESOS | G56: CUOTA | I56: Pago de cuota [C-0002] de Ruth Ferreyra por actividad de Complemento | N56: 29.671.795 | P56: 30000 | R56: 0 | T56: Transferencia | V56: PAGADO | Y56: COMPLETADO | AB56: F-0105 | AD56: 46174.431 | AF56: Silvia | AI56: Fernandez | AL56: 28.957.166 | AN56: 3764331464 | AP56: Funcional | AR56: Completa | AT56: 35000 | AV56: Abandonado | AY56: Natanael | BA56: SIN PAGOS
B57: I-0895 | C57: 46209.798 | E57: INGRESOS | G57: CUOTA | I57: Pago de cuota [F-0026] de Zoe Tainski por actividad de Funcional | N57: 36.408.521 | P57: 5000 | R57: 0 | T57: Transferencia | V57: PAGADO | Y57: COMPLETADO | AB57: F-0104 | AD57: 46170.711 | AF57: Dahiana | AI57: Da Silva | AL57: 35.456.307 | AN57: 3764729070 | AP57: Funcional | AR57: Reducida | AT57: 30000 | AV57: Al día | AY57: Natanael | BA57: 46236
B58: I-0894 | C58: 46209.797 | E58: INGRESOS | G58: CUOTA | I58: Pago de cuota [F-0026] de Zoe Tainski por actividad de Funcional | N58: 36.408.521 | P58: 25000 | R58: 0 | T58: Efectivo | V58: PAGADO | Y58: COMPLETADO | AB58: F-0103 | AD58: 46169.989 | AF58: Candela | AI58: Villalba | AL58: 46.551.204 | AN58: 3765103178 | AP58: Funcional | AR58: Reducida | AT58: 30000 | AV58: Adeudando | AY58: Natanael | BA58: 46200
B59: I-0893 | C59: 46209.788 | E59: INGRESOS | G59: CUOTA | I59: Pago de cuota [F-0032] de Gabriela Escobar por actividad de Funcional | N59: 41.761.422 | P59: 30000 | R59: 0 | T59: Efectivo | V59: PAGADO | Y59: COMPLETADO | AB59: C-0102 | AD59: 46169.703 | AF59: Celia Rita | AI59: Montenegro | AL59: 04.789.004 | AN59: 3764812698 | AP59: Complemento | AR59: Completa | AT59: 30000 | AV59: Al día | AY59: Natanael | BA59: 46237
B60: I-0886 | C60: 46209.749 | E60: INGRESOS | G60: CUOTA | I60: Pago de cuota [F-0016] de Amelia Escurdia por actividad de Funcional | N60: 18.438.313 | P60: 30000 | R60: 0 | T60: Efectivo | V60: PAGADO | Y60: COMPLETADO | AB60: C-0101 | AD60: 46168.796 | AF60: Liliana | AI60: Velloso | AL60: 31.330.650 | AN60: 3764534337 | AP60: Complemento | AR60: Completa | AT60: 30000 | AV60: Al día | AY60: Natanael | BA60: 46240
B61: I-0885 | C61: 46209.748 | E61: INGRESOS | G61: CUOTA | I61: Pago de cuota [F-0015] de Antonella Kerber por actividad de Funcional | N61: 46.833.183 | P61: 30000 | R61: 0 | T61: Efectivo | V61: PAGADO | Y61: COMPLETADO | AB61: F-0100 | AD61: 46168.431 | AF61: Camila | AI61: Ortiz | AL61: 44.539.682 | AN61: 3764103083 | AP61: Funcional | AR61: Reducida | AT61: 30000 | AV61: Adeudando | AY61: Natanael | BA61: 46199
